Workbook
Name Average: 'Yield_Sensitivity (2)'!$O$5
Name AverageSI: Calculator2!$E$20
Name AverageYG: Calculator2!$E$21
Name AVg: Calculator!$D$14
Name Avg_SI: Calculator2!#REF!
Name Avg_Yield: Calculator!$C$14
Name Avg_YP: Calculator2!#REF!
Name C_Zone: 'Dashboard2 (2)'!$G$6
Name C_Zone: 'Dashboard2 (3)'!#REF!
Name C_Zone: Dashboard2!$E$5
Name ClimateZ: 'Dashboard2 (3)'!$G$7
Name Gap: Calculator!$L$14
Name HYear: Dashboard!$L$7
Name Index: Calculator!$G$14
Name Interpretation: Calculator2!$G$6
Name Investment: Calculator2!$G$7
Name Label: Calculator2!$G$5
Name Label1: Calculator2!$G$5
Name Maximum: 'Yield_Sensitivity (2)'!$O$6
Name Stress: Calculator!$G$14
Name Year: Dashboard!$L$7
Name Yield_GAp: 'Yield_Sensitivity (2)'!$O$8
Name Zone: Dashboard!$G$3

Sheet Info
A1: Information below captures the details about the source of the data
A2: Information on the contents of this GYGA Export file:
A4: The information in this file is distributed under the Creative Commons Attribution-NonCommercial-ShareAlike 3.0 Unported (CC BY-NC-SA 3.0) license
A5: For more information on the license please visit:
A6: https://creativecommons.org/licenses/by-nc-sa/3.0/
A9: The unit of the presented yield levels (YP, YW etc) is 'tons per harvested hectare at standard moisture content'
A10: The unit of the presented water productivity levels (WPP, WPA) is 'kg per mm water per hectare'
A11: The temporal coefficient of variation (CV_T) for a country gets only calculated if at least 5 years of overlapping data are available for ALL contributing climate zones
A12: The same rule is applied to CV_T for a climate zone: it only gets calculated if at least 5 years of overlapping data are available for ALL contributing stations
A14: For definitions and methods please visit the GYGA website:
A15: http://www.yieldgap.org/glossary
A16: http://www.yieldgap.org/methods-overview
A18: Creation date: | C18: 11-Oct-2016
A19: Source: | C19: http://www.yieldgap.org/gygamaps/excel/GygaNigeria.xlsx
A21: Notes for Yield Sensitivity Sheet
A22: TimesrYldExpYld(T) | C22: actual linear trend yield. This was derived using the trend equation previously derived for each climate zone
A23: Detrended yldY/T=SI | C23: projected linear trend yield using the multiplicative detrending method
A24: RYVariability | C24: yield sensitivity i.e. projected/actual
A26: Notes for TrendEqn Sheet
A27: The trend equations were derived using the time series data for each climate zone

Sheet TrendEqn
A1: CLIMATEZONE | B1: Yield Trend equation
A2: 9101 | B2: y = 0.169x - 337.07
A3: 9301 | B3: y = 0.0797x - 158.27
A4: 9401 | B4: y = 0.0777x - 153.88
A5: 9501 | B5: y = 0.0624x - 123.4
A6: 9701 | B6: y = 0.041x - 80.197
A7: 9801 | B7: y = 0.0141x - 26.355
A8: 9901 | B8: y = -0.0482x + 98.149
A9: 10101 | B9: y = 0.0366x - 72.364
A10: 10301 | B10: y = 0.0784x - 155.91
A11: 10401 | B11: y = 0.0432x - 85.175
A12: 10501 | B12: y = -0.0423x + 86.622
A13: 10901 | B13: y = -0.0232x + 48.558

Sheet Yield_Sensitivity
A1: CLIMATEZONE | B1: CROP | C1: HARVEST_YEAR (X) | D1: YA (Y) | E1: YW | F1: YP | G1: WPP | H1: WPA | I1: TimesrYldExpYld(T) | J1: Detrended yldY/T=SI | K1: RYVariability
A2: 9101 | B2: Rainfed maize | C2: 2002 | D2: 1.5 | E2: 0.891 | F2: 11.1 | G2: 3.1484099 | H2: 5.3003534 | I2: =0.169*C2-337.07 -> 1.268 | J2: =D2/I2 -> 1.1829653 | K2: =(J2/I2) -> 0.93293793
A3: 9101 | B3: Rainfed maize | C3: 2003 | D3: 1.4 | E3: 9.011 | F3: 10.6 | G3: 20.000965 | H3: 3.1074632 | I3: =0.169*C3-337.07 -> 1.437 | J3: =D3/I3 -> 0.97425191 | K3: =(J3/I3) -> 0.67797628
A4: 9101 | B4: Rainfed maize | C4: 2004 | D4: 1.4 | E4: 9.69 | F4: 11.6 | G4: 23.098655 | H4: 3.337267 | I4: =0.169*C4-337.07 -> 1.606 | J4: =D4/I4 -> 0.87173101 | K4: =(J4/I4) -> 0.54279639
A5: 9101 | B5: Rainfed maize | C5: 2005 | D5: 1.5 | E5: 10.254 | F5: 10.8 | G5: 24.498445 | H5: 3.5837397 | I5: =0.169*C5-337.07 -> 1.775 | J5: =D5/I5 -> 0.84507042 | K5: =(J5/I5) -> 0.47609601
A6: 9101 | B6: Rainfed maize | C6: 2006 | D6: 1.7 | I6: =0.169*C6-337.07 -> 1.944 | J6: =D6/I6 -> 0.8744856 | K6: =(J6/I6) -> 0.44983827
A7: 9101 | B7: Rainfed maize | C7: 2007 | D7: 1.8 | I7: =0.169*C7-337.07 -> 2.113 | J7: =D7/I7 -> 0.85186938 | K7: =(J7/I7) -> 0.40315636
A8: 9101 | B8: Rainfed maize | C8: 2008 | D8: 2.481 | I8: =0.169*C8-337.07 -> 2.282 | J8: =D8/I8 -> 1.0872042 | K8: =(J8/I8) -> 0.47642603
A9: 9101 | B9: Rainfed maize | C9: 2009 | D9: 2.492 | I9: =0.169*C9-337.07 -> 2.451 | J9: =D9/I9 -> 1.0167279 | K9: =(J9/I9) -> 0.41482165
A10: 9101 | B10: Rainfed maize | C10: 2010 | D10: 2.6 | I10: =0.169*C10-337.07 -> 2.62 | J10: =D10/I10 -> 0.99236641 | K10: =(J10/I10) -> 0.37876581
A11: 9301 | B11: Rainfed maize | C11: 2002 | D11: 1.6 | E11: 14.319192 | F11: 15.1 | G11: 24.853542 | H11: 2.7770887 | I11: =0.0797*C11-158.27 -> 1.2894 | J11: =D11/I11 -> 1.2408872 | K11: =(J11/I11) -> 0.96237571
A12: 9301 | B12: Rainfed maize | C12: 2003 | D12: 1.5 | E12: 7.7272727 | F12: 13.9 | G12: 13.883815 | H12: 2.6950935 | I12: =0.0797*C12-158.27 -> 1.3691 | J12: =D12/I12 -> 1.0956103 | K12: =(J12/I12) -> 0.80024122
A13: 9301 | B13: Rainfed maize | C13: 2004 | D13: 1.4 | E13: 11.790909 | F13: 14.3 | G13: 21.312106 | H13: 2.5305045 | I13: =0.0797*C13-158.27 -> 1.4488 | J13: =D13/I13 -> 0.96631695 | K13: =(J13/I13) -> 0.66697747
A14: 9301 | B14: Rainfed maize | C14: 2005 | D14: 1.5 | E14: 12.251515 | F14: 13.9 | G14: 21.879132 | H14: 2.678746 | I14: =0.0797*C14-158.27 -> 1.5285 | J14: =D14/I14 -> 0.98135427 | K14: =(J14/I14) -> 0.64203747
A15: 9301 | B15: Rainfed maize | C15: 2006 | D15: 1.5 | E15: 13.967677 | F15: 14 | G15: 24.509003 | H15: 2.6320415 | I15: =0.0797*C15-158.27 -> 1.6082 | J15: =D15/I15 -> 0.93271981 | K15: =(J15/I15) -> 0.5799775
A16: 9301 | B16: Rainfed maize | C16: 2007 | D16: 1.6 | E16: 13.712121 | F16: 14.3 | G16: 23.021624 | H16: 2.6862801 | I16: =0.0797*C16-158.27 -> 1.6879 | J16: =D16/I16 -> 0.94792346 | K16: =(J16/I16) -> 0.5615993
A17: 9301 | B17: Rainfed maize | C17: 2008 | D17: 1.671 | E17: 11.358586 | F17: 15 | G17: 18.35004 | H17: 2.6995364 | I17: =0.0797*C17-158.27 -> 1.7676 | J17: =D17/I17 -> 0.94534963 | K17: =(J17/I17) -> 0.53482102
A18: 9301 | B18: Rainfed maize | C18: 2009 | D18: 2.349 | E18: 11.327273 | F18: 12.9 | G18: 21.070454 | H18: 4.369498 | I18: =0.0797*C18-158.27 -> 1.8473 | J18: =D18/I18 -> 1.2715856 | K18: =(J18/I18) -> 0.68834816
A19: 9401 | B19: Rainfed maize | C19: 2002 | D19: 1.7 | E19: 12.4 | F19: 12.4 | G19: 19.84 | H19: 2.72 | I19: =0.0777*C19-153.88 -> 1.6754 | J19: =D19/I19 -> 1.0146831 | K19: =(J19/I19) -> 0.6056363
A20: 9401 | B20: Rainfed maize | C20: 2003 | D20: 1.7 | E20: 12.9 | F20: 12.9 | G20: 22.504068 | H20: 2.9656524 | I20: =0.0777*C20-153.88 -> 1.7531 | J20: =D20/I20 -> 0.9697108 | K20: =(J20/I20) -> 0.55314061
A21: 9401 | B21: Rainfed maize | C21: 2004 | D21: 1.9 | E21: 14.034 | F21: 14.1 | G21: 23.09773 | H21: 3.1270976 | I21: =0.0777*C21-153.88 -> 1.8308 | J21: =D21/I21 -> 1.0377977 | K21: =(J21/I21) -> 0.56685475
A22: 9401 | B22: Rainfed maize | C22: 2005 | D22: 2.1 | E22: 13.3 | F22: 13.3 | G22: 22.542373 | H22: 3.559322 | I22: =0.0777*C22-153.88 -> 1.9085 | J22: =D22/I22 -> 1.1003406 | K22: =(J22/I22) -> 0.57654733
A23: 9401 | B23: Rainfed maize | C23: 2006 | D23: 2.1 | E23: 14.2 | F23: 14.2 | G23: 24.956063 | H23: 3.6906854 | I23: =0.0777*C23-153.88 -> 1.9862 | J23: =D23/I23 -> 1.0572953 | K23: =(J23/I23) -> 0.53232068
A24: 9401 | B24: Rainfed maize | C24: 2007 | D24: 2.2 | E24: 14.18 | F24: 14.4 | G24: 23.078859 | H24: 3.580641 | I24: =0.0777*C24-153.88 -> 2.0639 | J24: =D24/I24 -> 1.0659431 | K24: =(J24/I24) -> 0.51647033
A25: 9401 | B25: Rainfed maize | C25: 2008 | D25: 2.251 | E25: 14.6 | F25: 14.6 | G25: 24.446205 | H25: 3.7690691 | I25: =0.0777*C25-153.88 -> 2.1416 | J25: =D25/I25 -> 1.0510833 | K25: =(J25/I25) -> 0.49079347
A26: 9401 | B26: Rainfed maize | C26: 2009 | D26: 2.254 | E26: 12.511 | F26: 14.9 | G26: 21.474113 | H26: 3.8688075 | I26: =0.0777*C26-153.88 -> 2.2193 | J26: =D26/I26 -> 1.0156356 | K26: =(J26/I26) -> 0.4576378
A27: 9401 | B27: Rainfed maize | C27: 2010 | D27: 2.25 | E27: 12.768 | F27: 12.9 | G27: 23.671003 | H27: 4.1713468 | I27: =0.0777*C27-153.88 -> 2.297 | J27: =D27/I27 -> 0.97953853 | K27: =(J27/I27) -> 0.42644255
A28: 9501 | B28: Rainfed maize | C28: 2002 | D28: 1.7518344 | E28: 15.734696 | F28: 15.896331 | G28: 28.087091 | H28: 3.1270976 | I28: =0.0624*C28-123.4 -> 1.5248 | J28: =D28/I28 -> 1.1488945 | K28: =(J28/I28) -> 0.75347227
A29: 9501 | B29: Rainfed maize | C29: 2003 | D29: 1.6777515 | E29: 15.806991 | F29: 16.503669 | G29: 29.107957 | H29: 3.089514 | I29: =0.0624*C29-123.4 -> 1.5872 | J29: =D29/I29 -> 1.0570511 | K29: =(J29/I29) -> 0.66598483
A30: 9501 | B30: Rainfed maize | C30: 2004 | D30: 1.7518344 | E30: 15.88467 | F30: 15.992426 | G30: 30.937619 | H30: 3.4119428 | I30: =0.0624*C30-123.4 -> 1.6496 | J30: =D30/I30 -> 1.0619752 | K30: =(J30/I30) -> 0.64377743
A31: 9501 | B31: Rainfed maize | C31: 2005 | D31: 1.6777515 | E31: 15.526096 | F31: 16.251834 | G31: 28.666328 | H31: 3.0976863 | I31: =0.0624*C31-123.4 -> 1.712 | J31: =D31/I31 -> 0.97999506 | K31: =(J31/I31) -> 0.57242702
A32: 9501 | B32: Rainfed maize | C32: 2006 | D32: 1.5777515 | E32: 15.229988 | F32: 16.074083 | G32: 29.771856 | H32: 3.0842174 | I32: =0.0624*C32-123.4 -> 1.7744 | J32: =D32/I32 -> 0.88917467 | K32: =(J32/I32) -> 0.50111287
A33: 9501 | B33: Rainfed maize | C33: 2007 | D33: 1.5518344 | E33: 11.256912 | F33: 14.088522 | G33: 22.47399 | H33: 3.0981775 | I33: =0.0624*C33-123.4 -> 1.8368 | J33: =D33/I33 -> 0.84485756 | K33: =(J33/I33) -> 0.45996165
A34: 9501 | B34: Rainfed maize | C34: 2008 | D34: 1.6187255 | E34: 15.16547 | F34: 15.255267 | G34: 29.295784 | H34: 3.1269611 | I34: =0.0624*C34-123.4 -> 1.8992 | J34: =D34/I34 -> 0.85231966 | K34: =(J34/I34) -> 0.44877826
A35: 9501 | B35: Rainfed maize | C35: 2009 | D35: 2.038484 | E35: 14.293833 | F35: 15.914675 | G35: 26.538881 | H35: 3.7847852 | I35: =0.0624*C35-123.4 -> 1.9616 | J35: =D35/I35 -> 1.0391946 | K35: =(J35/I35) -> 0.52976884
A36: 9501 | B36: Rainfed maize | C36: 2010 | D36: 2.5155146 | E36: 9.4682642 | F36: 15.974083 | G36: 19.047498 | H36: 5.0605114 | I36: =0.0624*C36-123.4 -> 2.024 | J36: =D36/I36 -> 1.2428432 | K36: =(J36/I36) -> 0.61405296
A37: 9701 | B37: Rainfed maize | C37: 2002 | D37: 2.2 | E37: 0 | F37: 15.1 | G37: 0 | I37: =0.041*C37-80.197 -> 1.885 | J37: =D37/I37 -> 1.1671088 | K37: =(J37/I37) -> 0.61915584
A38: 9701 | B38: Rainfed maize | C38: 2003 | D38: 2.1 | E38: 0 | F38: 14.9 | G38: 0 | I38: =0.041*C38-80.197 -> 1.926 | J38: =D38/I38 -> 1.0903427 | K38: =(J38/I38) -> 0.56611769
A39: 9701 | B39: Rainfed maize | C39: 2004 | D39: 2.1 | E39: 8.077 | F39: 15.4 | G39: 19.102299 | H39: 4.9665505 | I39: =0.041*C39-80.197 -> 1.967 | J39: =D39/I39 -> 1.0676157 | K39: =(J39/I39) -> 0.54276343
A40: 9701 | B40: Rainfed maize | C40: 2005 | D40: 2.1 | E40: 2.618 | F40: 14 | G40: 6.0923176 | H40: 4.8868857 | I40: =0.041*C40-80.197 -> 2.008 | J40: =D40/I40 -> 1.0458167 | K40: =(J40/I40) -> 0.52082507
...

Sheet Yield_Chart_Used
A3: Average of Actual_Yield (YA) | B3: Climate_Zone
A4: Harvest_Year | B4: 9101 | C4: 9301 | D4: Grand Total
A5: 2002 | B5: 1.5 | C5: 1.6 | D5: 1.55
A6: 2003 | B6: 1.4 | C6: 1.5 | D6: 1.45
A7: 2004 | B7: 1.4 | C7: 1.4 | D7: 1.4
A8: 2005 | B8: 1.5 | C8: 1.5 | D8: 1.5
A9: 2006 | B9: 1.7 | C9: 1.5 | D9: 1.6
A10: 2007 | B10: 1.8 | C10: 1.6 | D10: 1.7
A11: 2008 | B11: 2.481 | C11: 1.671 | D11: 2.076
A12: 2009 | B12: 2.492 | C12: 2.349 | D12: 2.4205
A13: 2010 | B13: 2.6 | D13: 2.6
A14: Grand Total | B14: 1.8747778 | C14: 1.64 | D14: 1.7642941
E17: Grand average of all climate zone average
E18: =AVERAGE(B14:M14) -> 1.7596906

Sheet Sheet1
A3: Average of Actual_Yield (YA) | B3: Harvest_Year
A4: Climate_Zone | B4: 2002 | C4: 2003 | D4: 2004 | E4: 2005 | F4: 2006 | G4: 2007 | H4: 2008 | I4: 2009 | J4: 2010 | K4: Grand Total
A5: 9101 | B5: 1.5 | C5: 1.4 | D5: 1.4 | E5: 1.5 | F5: 1.7 | G5: 1.8 | H5: 2.481 | I5: 2.492 | J5: 2.6 | K5: 1.8747778
A6: 9301 | B6: 1.6 | C6: 1.5 | D6: 1.4 | E6: 1.5 | F6: 1.5 | G6: 1.6 | H6: 1.671 | I6: 2.349 | K6: 1.64
A7: 9401 | B7: 1.7 | C7: 1.7 | D7: 1.9 | E7: 2.1 | F7: 2.1 | G7: 2.2 | H7: 2.251 | I7: 2.254 | J7: 2.25 | K7: 2.0505556
A8: 9501 | B8: 1.7518344 | C8: 1.6777515 | D8: 1.7518344 | E8: 1.6777515 | F8: 1.5777515 | G8: 1.5518344 | H8: 1.6187255 | I8: 2.038484 | J8: 2.5155146 | K8: 1.7957202
A9: 9701 | B9: 2.2 | C9: 2.1 | D9: 2.1 | E9: 2.1 | F9: 1.9 | G9: 1.9 | H9: 1.929 | I9: 2.355 | J9: 2.76 | K9: 2.1493333
A10: 9801 | B10: 1.9 | C10: 1.9 | D10: 1.8 | E10: 1.9 | F10: 1.9 | G10: 1.9 | H10: 1.9755 | I10: 1.9715 | J10: 1.97 | K10: 1.913
A11: 9901 | B11: 1.5271901 | C11: 1.6987485 | D11: 1.5518772 | E11: 1.5765644 | F11: 1.6012515 | G11: 1.5259386 | H11: 1.2504672 | I11: 1.2512996 | J11: 1.3032613 | K11: 1.4762887
A12: 10101 | B12: 0.91689226 | C12: 0.91689226 | D12: 0.92533839 | E12: 1.0168923 | F12: 1.1084461 | G12: 1.1168923 | H12: 1.1455815 | I12: 1.1419193 | J12: 1.1619599 | K12: 1.0500905
A13: 10301 | B13: 1.1 | C13: 1.1 | D13: 1.1 | E13: 1.2 | F13: 1.2 | G13: 1.2 | H13: 1.246 | I13: 1.81 | J13: 1.67 | K13: 1.2917778
A14: 10401 | B14: 1.3583094 | C14: 1.3583094 | D14: 1.4166187 | E14: 1.5166187 | F14: 1.6166187 | G14: 1.6166187 | H14: 1.5617907 | I14: 1.6517253 | J14: 1.6890203 | K14: 1.5317367
A15: 10501 | B15: 1.8 | C15: 1.9 | D15: 1.9 | E15: 1.8 | F15: 1.8 | G15: 1.6 | H15: 1.637 | I15: 1.629 | J15: 1.55 | K15: 1.7351111
A16: 10901 | B16: 1.8 | C16: 1.8 | D16: 2 | E16: 2.2 | F16: 2.2 | G16: 2.1 | H16: 1.873 | I16: 1.613 | J16: 1.68 | K16: 1.9184444
A17: Grand Total | B17: 1.5961855 | C17: 1.5876418 | D17: 1.6038057 | E17: 1.6739856 | F17: 1.6836723 | G17: 1.6759403 | H17: 1.7200054 | I17: 1.879744 | J17: 1.9227051 | K17: 1.702818

Sheet Sheet2
A2: Climate_Zone | B2: 2002 | C2: 2003 | D2: 2004 | E2: 2005 | F2: 2006 | G2: 2007 | H2: 2008 | I2: 2009 | J2: 2010 | K2: Yield_Trends
A3: 9101 | B3: 1.5 | C3: 1.4 | D3: 1.4 | E3: 1.5 | F3: 1.7 | G3: 1.8 | H3: 2.481 | I3: 2.492 | J3: 2.6
A4: 9301 | B4: 1.6 | C4: 1.5 | D4: 1.4 | E4: 1.5 | F4: 1.5 | G4: 1.6 | H4: 1.671 | I4: 2.349
A5: 9401 | B5: 1.7 | C5: 1.7 | D5: 1.9 | E5: 2.1 | F5: 2.1 | G5: 2.2 | H5: 2.251 | I5: 2.254 | J5: 2.25
A6: 9501 | B6: 1.7518344 | C6: 1.6777515 | D6: 1.7518344 | E6: 1.6777515 | F6: 1.5777515 | G6: 1.5518344 | H6: 1.6187255 | I6: 2.038484 | J6: 2.5155146
A7: 9701 | B7: 2.2 | C7: 2.1 | D7: 2.1 | E7: 2.1 | F7: 1.9 | G7: 1.9 | H7: 1.929 | I7: 2.355 | J7: 2.76
A8: 9801 | B8: 1.9 | C8: 1.9 | D8: 1.8 | E8: 1.9 | F8: 1.9 | G8: 1.9 | H8: 1.9755 | I8: 1.9715 | J8: 1.97
A9: 9901 | B9: 1.5271901 | C9: 1.6987485 | D9: 1.5518772 | E9: 1.5765644 | F9: 1.6012515 | G9: 1.5259386 | H9: 1.2504672 | I9: 1.2512996 | J9: 1.3032613
A10: 10101 | B10: 0.91689226 | C10: 0.91689226 | D10: 0.92533839 | E10: 1.0168923 | F10: 1.1084461 | G10: 1.1168923 | H10: 1.1455815 | I10: 1.1419193 | J10: 1.1619599
A11: 10301 | B11: 1.1 | C11: 1.1 | D11: 1.1 | E11: 1.2 | F11: 1.2 | G11: 1.2 | H11: 1.246 | I11: 1.81 | J11: 1.67
A12: 10401 | B12: 1.3583094 | C12: 1.3583094 | D12: 1.4166187 | E12: 1.5166187 | F12: 1.6166187 | G12: 1.6166187 | H12: 1.5617907 | I12: 1.6517253 | J12: 1.6890203
A13: 10501 | B13: 1.8 | C13: 1.9 | D13: 1.9 | E13: 1.8 | F13: 1.8 | G13: 1.6 | H13: 1.637 | I13: 1.629 | J13: 1.55
A14: 10901 | B14: 1.8 | C14: 1.8 | D14: 2 | E14: 2.2 | F14: 2.2 | G14: 2.1 | H14: 1.873 | I14: 1.613 | J14: 1.68

Sheet Calculator
A1: Average of Actual_Yield (YA) | B1: Column Labels
A2: Row Labels | B2: 9101 | C2: 9301 | D2: 9401 | E2: 9501 | F2: 9701 | G2: 9801 | H2: 9901 | I2: 10101 | J2: 10301 | K2: 10401 | L2: 10501 | M2: 10901 | N2: Grand Total
A3: 2002 | B3: 1.5 | C3: 1.6 | D3: 1.7 | E3: 1.7518344 | F3: 2.2 | G3: 1.9 | H3: 1.5271901 | I3: 0.91689226 | J3: 1.1 | K3: 1.3583094 | L3: 1.8 | M3: 1.8 | N3: 1.5961855
A4: 2003 | B4: 1.4 | C4: 1.5 | D4: 1.7 | E4: 1.6777515 | F4: 2.1 | G4: 1.9 | H4: 1.6987485 | I4: 0.91689226 | J4: 1.1 | K4: 1.3583094 | L4: 1.9 | M4: 1.8 | N4: 1.5876418
A5: 2004 | B5: 1.4 | C5: 1.4 | D5: 1.9 | E5: 1.7518344 | F5: 2.1 | G5: 1.8 | H5: 1.5518772 | I5: 0.92533839 | J5: 1.1 | K5: 1.4166187 | L5: 1.9 | M5: 2 | N5: 1.6038057
A6: 2005 | B6: 1.5 | C6: 1.5 | D6: 2.1 | E6: 1.6777515 | F6: 2.1 | G6: 1.9 | H6: 1.5765644 | I6: 1.0168923 | J6: 1.2 | K6: 1.5166187 | L6: 1.8 | M6: 2.2 | N6: 1.6739856
A7: 2006 | B7: 1.7 | C7: 1.5 | D7: 2.1 | E7: 1.5777515 | F7: 1.9 | G7: 1.9 | H7: 1.6012515 | I7: 1.1084461 | J7: 1.2 | K7: 1.6166187 | L7: 1.8 | M7: 2.2 | N7: 1.6836723
A8: 2007 | B8: 1.8 | C8: 1.6 | D8: 2.2 | E8: 1.5518344 | F8: 1.9 | G8: 1.9 | H8: 1.5259386 | I8: 1.1168923 | J8: 1.2 | K8: 1.6166187 | L8: 1.6 | M8: 2.1 | N8: 1.6759403
A9: 2008 | B9: 2.481 | C9: 1.671 | D9: 2.251 | E9: 1.6187255 | F9: 1.929 | G9: 1.9755 | H9: 1.2504672 | I9: 1.1455815 | J9: 1.246 | K9: 1.5617907 | L9: 1.637 | M9: 1.873 | N9: 1.7200054
A10: 2009 | B10: 2.492 | C10: 2.349 | D10: 2.254 | E10: 2.038484 | F10: 2.355 | G10: 1.9715 | H10: 1.2512996 | I10: 1.1419193 | J10: 1.81 | K10: 1.6517253 | L10: 1.629 | M10: 1.613 | N10: 1.879744
A11: 2010 | B11: 2.6 | D11: 2.25 | E11: 2.5155146 | F11: 2.76 | G11: 1.97 | H11: 1.3032613 | I11: 1.1619599 | J11: 1.67 | K11: 1.6890203 | L11: 1.55 | M11: 1.68 | N11: 1.9227051
A12: Grand Total | B12: 1.8747778 | C12: 1.64 | D12: 2.0505556 | E12: 1.7957202 | F12: 2.1493333 | G12: 1.913 | H12: 1.4762887 | I12: 1.0500905 | J12: 1.2917778 | K12: 1.5317367 | L12: 1.7351111 | M12: 1.9184444 | N12: 1.702818
B13: Avg_Actual_Yield | C13: Refrence | F13: Avg_Stress_Index | G13: Reference | J13: Avg_Yield_Gap
A14: {=_xlfn.UNIQUE(Table1[Climate_Zone])} -> 9101 | B14: =AVERAGEIF(Table1[Climate_Zone],Calculator!A14,Table1[Actual_Yield (YA)]) -> 1.8747778 | C14: {=_xlfn.XLOOKUP(Zone,_xlfn.ANCHORARRAY(A14),B14:B25)} -> 2.1493333 | F14: =AVERAGEIF(Table1[Climate_Zone],Calculator!A14,Table1[Stress_Index]) -> 0.9662969 | G14: {=_xlfn.XLOOKUP(Zone,_xlfn.ANCHORARRAY(A14),F14:F25)} -> 1.0493217 | J14: =AVERAGEIF(Table1[Climate_Zone],Calculator!A14,Table1[Calculated_Yield_Gap]) -> 9.575 | L14: {=_xlfn.XLOOKUP(Zone,_xlfn.ANCHORARRAY(A14),J14:J25)} -> 13.206222
A15: 9301 | B15: =AVERAGEIF(Table1[Climate_Zone],Calculator!A15,Table1[Actual_Yield (YA)]) -> 1.64 | F15: =AVERAGEIF(Table1[Climate_Zone],Calculator!A15,Table1[Stress_Index]) -> 1.0477184 | J15: =AVERAGEIF(Table1[Climate_Zone],Calculator!A15,Table1[Calculated_Yield_Gap]) -> 12.535
A16: 9401 | B16: =AVERAGEIF(Table1[Climate_Zone],Calculator!A16,Table1[Actual_Yield (YA)]) -> 2.0505556 | F16: =AVERAGEIF(Table1[Climate_Zone],Calculator!A16,Table1[Stress_Index]) -> 1.0324476 | J16: =AVERAGEIF(Table1[Climate_Zone],Calculator!A16,Table1[Calculated_Yield_Gap]) -> 11.693889
A17: 9501 | B17: =AVERAGEIF(Table1[Climate_Zone],Calculator!A17,Table1[Actual_Yield (YA)]) -> 1.7957202 | F17: =AVERAGEIF(Table1[Climate_Zone],Calculator!A17,Table1[Stress_Index]) -> 1.0129228 | J17: =AVERAGEIF(Table1[Climate_Zone],Calculator!A17,Table1[Calculated_Yield_Gap]) -> 13.976601
A18: 9701 | B18: =AVERAGEIF(Table1[Climate_Zone],Calculator!A18,Table1[Actual_Yield (YA)]) -> 2.1493333 | F18: =AVERAGEIF(Table1[Climate_Zone],Calculator!A18,Table1[Stress_Index]) -> 1.0493217 | J18: =AVERAGEIF(Table1[Climate_Zone],Calculator!A18,Table1[Calculated_Yield_Gap]) -> 13.206222
A19: 9801 | B19: =AVERAGEIF(Table1[Climate_Zone],Calculator!A19,Table1[Actual_Yield (YA)]) -> 1.913 | F19: =AVERAGEIF(Table1[Climate_Zone],Calculator!A19,Table1[Stress_Index]) -> 0.9913971 | J19: =AVERAGEIF(Table1[Climate_Zone],Calculator!A19,Table1[Calculated_Yield_Gap]) -> 12.842556
A20: 9901 | B20: =AVERAGEIF(Table1[Climate_Zone],Calculator!A20,Table1[Actual_Yield (YA)]) -> 1.4762887 | F20: =AVERAGEIF(Table1[Climate_Zone],Calculator!A20,Table1[Stress_Index]) -> 1.0111898 | J20: =AVERAGEIF(Table1[Climate_Zone],Calculator!A20,Table1[Calculated_Yield_Gap]) -> 11.403398
A21: 10101 | B21: =AVERAGEIF(Table1[Climate_Zone],Calculator!A21,Table1[Actual_Yield (YA)]) -> 1.0500905 | F21: =AVERAGEIF(Table1[Climate_Zone],Calculator!A21,Table1[Stress_Index]) -> 0.99464684 | J21: =AVERAGEIF(Table1[Climate_Zone],Calculator!A21,Table1[Calculated_Yield_Gap]) -> 9.8128224
A22: 10301 | B22: =AVERAGEIF(Table1[Climate_Zone],Calculator!A22,Table1[Actual_Yield (YA)]) -> 1.2917778 | F22: =AVERAGEIF(Table1[Climate_Zone],Calculator!A22,Table1[Stress_Index]) -> 0.94974883 | J22: =AVERAGEIF(Table1[Climate_Zone],Calculator!A22,Table1[Calculated_Yield_Gap]) -> 13.641556
A23: 10401 | B23: =AVERAGEIF(Table1[Climate_Zone],Calculator!A23,Table1[Actual_Yield (YA)]) -> 1.5317367 | F23: =AVERAGEIF(Table1[Climate_Zone],Calculator!A23,Table1[Stress_Index]) -> 1.032144 | J23: =AVERAGEIF(Table1[Climate_Zone],Calculator!A23,Table1[Calculated_Yield_Gap]) -> 13.561283
A24: 10501 | B24: =AVERAGEIF(Table1[Climate_Zone],Calculator!A24,Table1[Actual_Yield (YA)]) -> 1.7351111 | F24: =AVERAGEIF(Table1[Climate_Zone],Calculator!A24,Table1[Stress_Index]) -> 0.98117347 | J24: =AVERAGEIF(Table1[Climate_Zone],Calculator!A24,Table1[Calculated_Yield_Gap]) -> 13.487111
A25: 10901 | B25: =AVERAGEIF(Table1[Climate_Zone],Calculator!A25,Table1[Actual_Yield (YA)]) -> 1.9184444 | F25: =AVERAGEIF(Table1[Climate_Zone],Calculator!A25,Table1[Stress_Index]) -> 0.95017905 | J25: =AVERAGEIF(Table1[Climate_Zone],Calculator!A25,Table1[Calculated_Yield_Gap]) -> 12.970444

Sheet Validation_YA_SIchart
B1: Zone_Validation | D1: Average SI
B2: {=_xlfn.UNIQUE(Table1[Climate_Zone])} -> 9101 | D2: {=_xlfn.UNIQUE(Table1[Harvest_Year])} -> 2002 | E2: {=AVERAGE(IF((Table1[Harvest_Year]=Validation_YA_SIchart!D2)*(Table1[Climate_Zone]=Zone),Table1[Stress_Index]))} -> 1.1671088
B3: 9301 | D3: 2003 | E3: {=AVERAGE(IF((Table1[Harvest_Year]=Validation_YA_SIchart!D3)*(Table1[Climate_Zone]=Zone),Table1[Stress_Index]))} -> 1.0903427
B4: 9401 | D4: 2004 | E4: {=AVERAGE(IF((Table1[Harvest_Year]=Validation_YA_SIchart!D4)*(Table1[Climate_Zone]=Zone),Table1[Stress_Index]))} -> 1.0676157
B5: 9501 | D5: 2005 | E5: {=AVERAGE(IF((Table1[Harvest_Year]=Validation_YA_SIchart!D5)*(Table1[Climate_Zone]=Zone),Table1[Stress_Index]))} -> 1.0458167
B6: 9701 | D6: 2006 | E6: {=AVERAGE(IF((Table1[Harvest_Year]=Validation_YA_SIchart!D6)*(Table1[Climate_Zone]=Zone),Table1[Stress_Index]))} -> 0.9272816
B7: 9801 | D7: 2007 | E7: {=AVERAGE(IF((Table1[Harvest_Year]=Validation_YA_SIchart!D7)*(Table1[Climate_Zone]=Zone),Table1[Stress_Index]))} -> 0.90909091
B8: 9901 | D8: 2008 | E8: {=AVERAGE(IF((Table1[Harvest_Year]=Validation_YA_SIchart!D8)*(Table1[Climate_Zone]=Zone),Table1[Stress_Index]))} -> 0.90520882
B9: 10101 | D9: 2009 | E9: {=AVERAGE(IF((Table1[Harvest_Year]=Validation_YA_SIchart!D9)*(Table1[Climate_Zone]=Zone),Table1[Stress_Index]))} -> 1.0842541
B10: 10301 | D10: 2010 | E10: {=AVERAGE(IF((Table1[Harvest_Year]=Validation_YA_SIchart!D10)*(Table1[Climate_Zone]=Zone),Table1[Stress_Index]))} -> 1.2471758
B11: 10401
B12: 10501
B13: 10901

Sheet Yield_Sensitivity (2)
A1: Climate_Zone | B1: Crop | C1: Harvest_Year | D1: Actual_Yield (YA) | E1: YW | F1: Potential_Yield (YP) | G1: WPP | H1: WPA | I1: TimesrYldExpYld(T) | J1: Stress_Index | K1: RY_Variability | L1: Calculated_Yield_Gap
A2: 9101 | B2: Rainfed maize | C2: 2002 | D2: 1.5 | E2: 0.891 | F2: 11.1 | G2: 3.1484099 | H2: 5.3003534 | I2: =0.169*C2-337.07 -> 1.268 | J2: =D2/I2 -> 1.1829653 | K2: =(J2/I2) -> 0.93293793 | L2: =IF(OR(Table1[[#This Row],[Actual_Yield (YA)]]="",Table1[[#This Row],[Potential_Yield (YP)]]=""),"",Table1[[#This Row],[Potential_Yield (YP)]]-Table1[[#This Row],[Actual_Yield (YA)]]) -> 9.6
A3: 9101 | B3: Rainfed maize | C3: 2003 | D3: 1.4 | E3: 9.011 | F3: 10.6 | G3: 20.000965 | H3: 3.1074632 | I3: =0.169*C3-337.07 -> 1.437 | J3: =D3/I3 -> 0.97425191 | K3: =(J3/I3) -> 0.67797628 | L3: =IF(OR(Table1[[#This Row],[Actual_Yield (YA)]]="",Table1[[#This Row],[Potential_Yield (YP)]]=""),"",Table1[[#This Row],[Potential_Yield (YP)]]-Table1[[#This Row],[Actual_Yield (YA)]]) -> 9.2 | N3: Metrics | O3: Value
A4: 9101 | B4: Rainfed maize | C4: 2004 | D4: 1.4 | E4: 9.69 | F4: 11.6 | G4: 23.098655 | H4: 3.337267 | I4: =0.169*C4-337.07 -> 1.606 | J4: =D4/I4 -> 0.87173101 | K4: =(J4/I4) -> 0.54279639 | L4: =IF(OR(Table1[[#This Row],[Actual_Yield (YA)]]="",Table1[[#This Row],[Potential_Yield (YP)]]=""),"",Table1[[#This Row],[Potential_Yield (YP)]]-Table1[[#This Row],[Actual_Yield (YA)]]) -> 10.2 | N4: Minimum Actual Yield | O4: =MIN(Table1[Actual_Yield (YA)]) -> 0.91689226
A5: 9101 | B5: Rainfed maize | C5: 2005 | D5: 1.5 | E5: 10.254 | F5: 10.8 | G5: 24.498445 | H5: 3.5837397 | I5: =0.169*C5-337.07 -> 1.775 | J5: =D5/I5 -> 0.84507042 | K5: =(J5/I5) -> 0.47609601 | L5: =IF(OR(Table1[[#This Row],[Actual_Yield (YA)]]="",Table1[[#This Row],[Potential_Yield (YP)]]=""),"",Table1[[#This Row],[Potential_Yield (YP)]]-Table1[[#This Row],[Actual_Yield (YA)]]) -> 9.3 | N5: Average Actual Yield | O5: =AVERAGE(Table1[Actual_Yield (YA)]) -> 1.702818
A6: 9101 | B6: Rainfed maize | C6: 2006 | D6: 1.7 | I6: =0.169*C6-337.07 -> 1.944 | J6: =D6/I6 -> 0.8744856 | K6: =(J6/I6) -> 0.44983827 | L6: =IF(OR(Table1[[#This Row],[Actual_Yield (YA)]]="",Table1[[#This Row],[Potential_Yield (YP)]]=""),"",Table1[[#This Row],[Potential_Yield (YP)]]-Table1[[#This Row],[Actual_Yield (YA)]]) | N6: Maximum Actual Yield | O6: =MAX(Table1[Actual_Yield (YA)]) -> 2.76
A7: 9101 | B7: Rainfed maize | C7: 2007 | D7: 1.8 | I7: =0.169*C7-337.07 -> 2.113 | J7: =D7/I7 -> 0.85186938 | K7: =(J7/I7) -> 0.40315636 | L7: =IF(OR(Table1[[#This Row],[Actual_Yield (YA)]]="",Table1[[#This Row],[Potential_Yield (YP)]]=""),"",Table1[[#This Row],[Potential_Yield (YP)]]-Table1[[#This Row],[Actual_Yield (YA)]]) | N7: Avergae Potential Yield | O7: =AVERAGE(Table1[Potential_Yield (YP)]) -> 14.206583
A8: 9101 | B8: Rainfed maize | C8: 2008 | D8: 2.481 | I8: =0.169*C8-337.07 -> 2.282 | J8: =D8/I8 -> 1.0872042 | K8: =(J8/I8) -> 0.47642603 | L8: =IF(OR(Table1[[#This Row],[Actual_Yield (YA)]]="",Table1[[#This Row],[Potential_Yield (YP)]]=""),"",Table1[[#This Row],[Potential_Yield (YP)]]-Table1[[#This Row],[Actual_Yield (YA)]]) | N8: Yield Gap | O8: =O7-O5 -> 12.503765
A9: 9101 | B9: Rainfed maize | C9: 2009 | D9: 2.492 | I9: =0.169*C9-337.07 -> 2.451 | J9: =D9/I9 -> 1.0167279 | K9: =(J9/I9) -> 0.41482165 | L9: =IF(OR(Table1[[#This Row],[Actual_Yield (YA)]]="",Table1[[#This Row],[Potential_Yield (YP)]]=""),"",Table1[[#This Row],[Potential_Yield (YP)]]-Table1[[#This Row],[Actual_Yield (YA)]])
A10: 9101 | B10: Rainfed maize | C10: 2010 | D10: 2.6 | I10: =0.169*C10-337.07 -> 2.62 | J10: =D10/I10 -> 0.99236641 | K10: =(J10/I10) -> 0.37876581 | L10: =IF(OR(Table1[[#This Row],[Actual_Yield (YA)]]="",Table1[[#This Row],[Potential_Yield (YP)]]=""),"",Table1[[#This Row],[Potential_Yield (YP)]]-Table1[[#This Row],[Actual_Yield (YA)]])
A11: 9301 | B11: Rainfed maize | C11: 2002 | D11: 1.6 | E11: 14.319192 | F11: 15.1 | G11: 24.853542 | H11: 2.7770887 | I11: =0.0797*C11-158.27 -> 1.2894 | J11: =D11/I11 -> 1.2408872 | K11: =(J11/I11) -> 0.96237571 | L11: =IF(OR(Table1[[#This Row],[Actual_Yield (YA)]]="",Table1[[#This Row],[Potential_Yield (YP)]]=""),"",Table1[[#This Row],[Potential_Yield (YP)]]-Table1[[#This Row],[Actual_Yield (YA)]]) -> 13.5
A12: 9301 | B12: Rainfed maize | C12: 2003 | D12: 1.5 | E12: 7.7272727 | F12: 13.9 | G12: 13.883815 | H12: 2.6950935 | I12: =0.0797*C12-158.27 -> 1.3691 | J12: =D12/I12 -> 1.0956103 | K12: =(J12/I12) -> 0.80024122 | L12: =IF(OR(Table1[[#This Row],[Actual_Yield (YA)]]="",Table1[[#This Row],[Potential_Yield (YP)]]=""),"",Table1[[#This Row],[Potential_Yield (YP)]]-Table1[[#This Row],[Actual_Yield (YA)]]) -> 12.4
A13: 9301 | B13: Rainfed maize | C13: 2004 | D13: 1.4 | E13: 11.790909 | F13: 14.3 | G13: 21.312106 | H13: 2.5305045 | I13: =0.0797*C13-158.27 -> 1.4488 | J13: =D13/I13 -> 0.96631695 | K13: =(J13/I13) -> 0.66697747 | L13: =IF(OR(Table1[[#This Row],[Actual_Yield (YA)]]="",Table1[[#This Row],[Potential_Yield (YP)]]=""),"",Table1[[#This Row],[Potential_Yield (YP)]]-Table1[[#This Row],[Actual_Yield (YA)]]) -> 12.9
A14: 9301 | B14: Rainfed maize | C14: 2005 | D14: 1.5 | E14: 12.251515 | F14: 13.9 | G14: 21.879132 | H14: 2.678746 | I14: =0.0797*C14-158.27 -> 1.5285 | J14: =D14/I14 -> 0.98135427 | K14: =(J14/I14) -> 0.64203747 | L14: =IF(OR(Table1[[#This Row],[Actual_Yield (YA)]]="",Table1[[#This Row],[Potential_Yield (YP)]]=""),"",Table1[[#This Row],[Potential_Yield (YP)]]-Table1[[#This Row],[Actual_Yield (YA)]]) -> 12.4
A15: 9301 | B15: Rainfed maize | C15: 2006 | D15: 1.5 | E15: 13.967677 | F15: 14 | G15: 24.509003 | H15: 2.6320415 | I15: =0.0797*C15-158.27 -> 1.6082 | J15: =D15/I15 -> 0.93271981 | K15: =(J15/I15) -> 0.5799775 | L15: =IF(OR(Table1[[#This Row],[Actual_Yield (YA)]]="",Table1[[#This Row],[Potential_Yield (YP)]]=""),"",Table1[[#This Row],[Potential_Yield (YP)]]-Table1[[#This Row],[Actual_Yield (YA)]]) -> 12.5
A16: 9301 | B16: Rainfed maize | C16: 2007 | D16: 1.6 | E16: 13.712121 | F16: 14.3 | G16: 23.021624 | H16: 2.6862801 | I16: =0.0797*C16-158.27 -> 1.6879 | J16: =D16/I16 -> 0.94792346 | K16: =(J16/I16) -> 0.5615993 | L16: =IF(OR(Table1[[#This Row],[Actual_Yield (YA)]]="",Table1[[#This Row],[Potential_Yield (YP)]]=""),"",Table1[[#This Row],[Potential_Yield (YP)]]-Table1[[#This Row],[Actual_Yield (YA)]]) -> 12.7
A17: 9301 | B17: Rainfed maize | C17: 2008 | D17: 1.671 | E17: 11.358586 | F17: 15 | G17: 18.35004 | H17: 2.6995364 | I17: =0.0797*C17-158.27 -> 1.7676 | J17: =D17/I17 -> 0.94534963 | K17: =(J17/I17) -> 0.53482102 | L17: =IF(OR(Table1[[#This Row],[Actual_Yield (YA)]]="",Table1[[#This Row],[Potential_Yield (YP)]]=""),"",Table1[[#This Row],[Potential_Yield (YP)]]-Table1[[#This Row],[Actual_Yield (YA)]]) -> 13.329
A18: 9301 | B18: Rainfed maize | C18: 2009 | D18: 2.349 | E18: 11.327273 | F18: 12.9 | G18: 21.070454 | H18: 4.369498 | I18: =0.0797*C18-158.27 -> 1.8473 | J18: =D18/I18 -> 1.2715856 | K18: =(J18/I18) -> 0.68834816 | L18: =IF(OR(Table1[[#This Row],[Actual_Yield (YA)]]="",Table1[[#This Row],[Potential_Yield (YP)]]=""),"",Table1[[#This Row],[Potential_Yield (YP)]]-Table1[[#This Row],[Actual_Yield (YA)]]) -> 10.551
A19: 9401 | B19: Rainfed maize | C19: 2002 | D19: 1.7 | E19: 12.4 | F19: 12.4 | G19: 19.84 | H19: 2.72 | I19: =0.0777*C19-153.88 -> 1.6754 | J19: =D19/I19 -> 1.0146831 | K19: =(J19/I19) -> 0.6056363 | L19: =IF(OR(Table1[[#This Row],[Actual_Yield (YA)]]="",Table1[[#This Row],[Potential_Yield (YP)]]=""),"",Table1[[#This Row],[Potential_Yield (YP)]]-Table1[[#This Row],[Actual_Yield (YA)]]) -> 10.7
A20: 9401 | B20: Rainfed maize | C20: 2003 | D20: 1.7 | E20: 12.9 | F20: 12.9 | G20: 22.504068 | H20: 2.9656524 | I20: =0.0777*C20-153.88 -> 1.7531 | J20: =D20/I20 -> 0.9697108 | K20: =(J20/I20) -> 0.55314061 | L20: =IF(OR(Table1[[#This Row],[Actual_Yield (YA)]]="",Table1[[#This Row],[Potential_Yield (YP)]]=""),"",Table1[[#This Row],[Potential_Yield (YP)]]-Table1[[#This Row],[Actual_Yield (YA)]]) -> 11.2
A21: 9401 | B21: Rainfed maize | C21: 2004 | D21: 1.9 | E21: 14.034 | F21: 14.1 | G21: 23.09773 | H21: 3.1270976 | I21: =0.0777*C21-153.88 -> 1.8308 | J21: =D21/I21 -> 1.0377977 | K21: =(J21/I21) -> 0.56685475 | L21: =IF(OR(Table1[[#This Row],[Actual_Yield (YA)]]="",Table1[[#This Row],[Potential_Yield (YP)]]=""),"",Table1[[#This Row],[Potential_Yield (YP)]]-Table1[[#This Row],[Actual_Yield (YA)]]) -> 12.2
A22: 9401 | B22: Rainfed maize | C22: 2005 | D22: 2.1 | E22: 13.3 | F22: 13.3 | G22: 22.542373 | H22: 3.559322 | I22: =0.0777*C22-153.88 -> 1.9085 | J22: =D22/I22 -> 1.1003406 | K22: =(J22/I22) -> 0.57654733 | L22: =IF(OR(Table1[[#This Row],[Actual_Yield (YA)]]="",Table1[[#This Row],[Potential_Yield (YP)]]=""),"",Table1[[#This Row],[Potential_Yield (YP)]]-Table1[[#This Row],[Actual_Yield (YA)]]) -> 11.2
A23: 9401 | B23: Rainfed maize | C23: 2006 | D23: 2.1 | E23: 14.2 | F23: 14.2 | G23: 24.956063 | H23: 3.6906854 | I23: =0.0777*C23-153.88 -> 1.9862 | J23: =D23/I23 -> 1.0572953 | K23: =(J23/I23) -> 0.53232068 | L23: =IF(OR(Table1[[#This Row],[Actual_Yield (YA)]]="",Table1[[#This Row],[Potential_Yield (YP)]]=""),"",Table1[[#This Row],[Potential_Yield (YP)]]-Table1[[#This Row],[Actual_Yield (YA)]]) -> 12.1
A24: 9401 | B24: Rainfed maize | C24: 2007 | D24: 2.2 | E24: 14.18 | F24: 14.4 | G24: 23.078859 | H24: 3.580641 | I24: =0.0777*C24-153.88 -> 2.0639 | J24: =D24/I24 -> 1.0659431 | K24: =(J24/I24) -> 0.51647033 | L24: =IF(OR(Table1[[#This Row],[Actual_Yield (YA)]]="",Table1[[#This Row],[Potential_Yield (YP)]]=""),"",Table1[[#This Row],[Potential_Yield (YP)]]-Table1[[#This Row],[Actual_Yield (YA)]]) -> 12.2
A25: 9401 | B25: Rainfed maize | C25: 2008 | D25: 2.251 | E25: 14.6 | F25: 14.6 | G25: 24.446205 | H25: 3.7690691 | I25: =0.0777*C25-153.88 -> 2.1416 | J25: =D25/I25 -> 1.0510833 | K25: =(J25/I25) -> 0.49079347 | L25: =IF(OR(Table1[[#This Row],[Actual_Yield (YA)]]="",Table1[[#This Row],[Potential_Yield (YP)]]=""),"",Table1[[#This Row],[Potential_Yield (YP)]]-Table1[[#This Row],[Actual_Yield (YA)]]) -> 12.349
A26: 9401 | B26: Rainfed maize | C26: 2009 | D26: 2.254 | E26: 12.511 | F26: 14.9 | G26: 21.474113 | H26: 3.8688075 | I26: =0.0777*C26-153.88 -> 2.2193 | J26: =D26/I26 -> 1.0156356 | K26: =(J26/I26) -> 0.4576378 | L26: =IF(OR(Table1[[#This Row],[Actual_Yield (YA)]]="",Table1[[#This Row],[Potential_Yield (YP)]]=""),"",Table1[[#This Row],[Potential_Yield (YP)]]-Table1[[#This Row],[Actual_Yield (YA)]]) -> 12.646
A27: 9401 | B27: Rainfed maize | C27: 2010 | D27: 2.25 | E27: 12.768 | F27: 12.9 | G27: 23.671003 | H27: 4.1713468 | I27: =0.0777*C27-153.88 -> 2.297 | J27: =D27/I27 -> 0.97953853 | K27: =(J27/I27) -> 0.42644255 | L27: =IF(OR(Table1[[#This Row],[Actual_Yield (YA)]]="",Table1[[#This Row],[Potential_Yield (YP)]]=""),"",Table1[[#This Row],[Potential_Yield (YP)]]-Table1[[#This Row],[Actual_Yield (YA)]]) -> 10.65
A28: 9501 | B28: Rainfed maize | C28: 2002 | D28: 1.7518344 | E28: 15.734696 | F28: 15.896331 | G28: 28.087091 | H28: 3.1270976 | I28: =0.0624*C28-123.4 -> 1.5248 | J28: =D28/I28 -> 1.1488945 | K28: =(J28/I28) -> 0.75347227 | L28: =IF(OR(Table1[[#This Row],[Actual_Yield (YA)]]="",Table1[[#This Row],[Potential_Yield (YP)]]=""),"",Table1[[#This Row],[Potential_Yield (YP)]]-Table1[[#This Row],[Actual_Yield (YA)]]) -> 14.144497
A29: 9501 | B29: Rainfed maize | C29: 2003 | D29: 1.6777515 | E29: 15.806991 | F29: 16.503669 | G29: 29.107957 | H29: 3.089514 | I29: =0.0624*C29-123.4 -> 1.5872 | J29: =D29/I29 -> 1.0570511 | K29: =(J29/I29) -> 0.66598483 | L29: =IF(OR(Table1[[#This Row],[Actual_Yield (YA)]]="",Table1[[#This Row],[Potential_Yield (YP)]]=""),"",Table1[[#This Row],[Potential_Yield (YP)]]-Table1[[#This Row],[Actual_Yield (YA)]]) -> 14.825917
A30: 9501 | B30: Rainfed maize | C30: 2004 | D30: 1.7518344 | E30: 15.88467 | F30: 15.992426 | G30: 30.937619 | H30: 3.4119428 | I30: =0.0624*C30-123.4 -> 1.6496 | J30: =D30/I30 -> 1.0619752 | K30: =(J30/I30) -> 0.64377743 | L30: =IF(OR(Table1[[#This Row],[Actual_Yield (YA)]]="",Table1[[#This Row],[Potential_Yield (YP)]]=""),"",Table1[[#This Row],[Potential_Yield (YP)]]-Table1[[#This Row],[Actual_Yield (YA)]]) -> 14.240592
A31: 9501 | B31: Rainfed maize | C31: 2005 | D31: 1.6777515 | E31: 15.526096 | F31: 16.251834 | G31: 28.666328 | H31: 3.0976863 | I31: =0.0624*C31-123.4 -> 1.712 | J31: =D31/I31 -> 0.97999506 | K31: =(J31/I31) -> 0.57242702 | L31: =IF(OR(Table1[[#This Row],[Actual_Yield (YA)]]="",Table1[[#This Row],[Potential_Yield (YP)]]=""),"",Table1[[#This Row],[Potential_Yield (YP)]]-Table1[[#This Row],[Actual_Yield (YA)]]) -> 14.574083
A32: 9501 | B32: Rainfed maize | C32: 2006 | D32: 1.5777515 | E32: 15.229988 | F32: 16.074083 | G32: 29.771856 | H32: 3.0842174 | I32: =0.0624*C32-123.4 -> 1.7744 | J32: =D32/I32 -> 0.88917467 | K32: =(J32/I32) -> 0.50111287 | L32: =IF(OR(Table1[[#This Row],[Actual_Yield (YA)]]="",Table1[[#This Row],[Potential_Yield (YP)]]=""),"",Table1[[#This Row],[Potential_Yield (YP)]]-Table1[[#This Row],[Actual_Yield (YA)]]) -> 14.496331
A33: 9501 | B33: Rainfed maize | C33: 2007 | D33: 1.5518344 | E33: 11.256912 | F33: 14.088522 | G33: 22.47399 | H33: 3.0981775 | I33: =0.0624*C33-123.4 -> 1.8368 | J33: =D33/I33 -> 0.84485756 | K33: =(J33/I33) -> 0.45996165 | L33: =IF(OR(Table1[[#This Row],[Actual_Yield (YA)]]="",Table1[[#This Row],[Potential_Yield (YP)]]=""),"",Table1[[#This Row],[Potential_Yield (YP)]]-Table1[[#This Row],[Actual_Yield (YA)]]) -> 12.536687
A34: 9501 | B34: Rainfed maize | C34: 2008 | D34: 1.6187255 | E34: 15.16547 | F34: 15.255267 | G34: 29.295784 | H34: 3.1269611 | I34: =0.0624*C34-123.4 -> 1.8992 | J34: =D34/I34 -> 0.85231966 | K34: =(J34/I34) -> 0.44877826 | L34: =IF(OR(Table1[[#This Row],[Actual_Yield (YA)]]="",Table1[[#This Row],[Potential_Yield (YP)]]=""),"",Table1[[#This Row],[Potential_Yield (YP)]]-Table1[[#This Row],[Actual_Yield (YA)]]) -> 13.636541
A35: 9501 | B35: Rainfed maize | C35: 2009 | D35: 2.038484 | E35: 14.293833 | F35: 15.914675 | G35: 26.538881 | H35: 3.7847852 | I35: =0.0624*C35-123.4 -> 1.9616 | J35: =D35/I35 -> 1.0391946 | K35: =(J35/I35) -> 0.52976884 | L35: =IF(OR(Table1[[#This Row],[Actual_Yield (YA)]]="",Table1[[#This Row],[Potential_Yield (YP)]]=""),"",Table1[[#This Row],[Potential_Yield (YP)]]-Table1[[#This Row],[Actual_Yield (YA)]]) -> 13.876191
A36: 9501 | B36: Rainfed maize | C36: 2010 | D36: 2.5155146 | E36: 9.4682642 | F36: 15.974083 | G36: 19.047498 | H36: 5.0605114 | I36: =0.0624*C36-123.4 -> 2.024 | J36: =D36/I36 -> 1.2428432 | K36: =(J36/I36) -> 0.61405296 | L36: =IF(OR(Table1[[#This Row],[Actual_Yield (YA)]]="",Table1[[#This Row],[Potential_Yield (YP)]]=""),"",Table1[[#This Row],[Potential_Yield (YP)]]-Table1[[#This Row],[Actual_Yield (YA)]]) -> 13.458568
A37: 9701 | B37: Rainfed maize | C37: 2002 | D37: 2.2 | E37: 0 | F37: 15.1 | G37: 0 | I37: =0.041*C37-80.197 -> 1.885 | J37: =D37/I37 -> 1.1671088 | K37: =(J37/I37) -> 0.61915584 | L37: =IF(OR(Table1[[#This Row],[Actual_Yield (YA)]]="",Table1[[#This Row],[Potential_Yield (YP)]]=""),"",Table1[[#This Row],[Potential_Yield (YP)]]-Table1[[#This Row],[Actual_Yield (YA)]]) -> 12.9
A38: 9701 | B38: Rainfed maize | C38: 2003 | D38: 2.1 | E38: 0 | F38: 14.9 | G38: 0 | I38: =0.041*C38-80.197 -> 1.926 | J38: =D38/I38 -> 1.0903427 | K38: =(J38/I38) -> 0.56611769 | L38: =IF(OR(Table1[[#This Row],[Actual_Yield (YA)]]="",Table1[[#This Row],[Potential_Yield (YP)]]=""),"",Table1[[#This Row],[Potential_Yield (YP)]]-Table1[[#This Row],[Actual_Yield (YA)]]) -> 12.8
A39: 9701 | B39: Rainfed maize | C39: 2004 | D39: 2.1 | E39: 8.077 | F39: 15.4 | G39: 19.102299 | H39: 4.9665505 | I39: =0.041*C39-80.197 -> 1.967 | J39: =D39/I39 -> 1.0676157 | K39: =(J39/I39) -> 0.54276343 | L39: =IF(OR(Table1[[#This Row],[Actual_Yield (YA)]]="",Table1[[#This Row],[Potential_Yield (YP)]]=""),"",Table1[[#This Row],[Potential_Yield (YP)]]-Table1[[#This Row],[Actual_Yield (YA)]]) -> 13.3
A40: 9701 | B40: Rainfed maize | C40: 2005 | D40: 2.1 | E40: 2.618 | F40: 14 | G40: 6.0923176 | H40: 4.8868857 | I40: =0.041*C40-80.197 -> 2.008 | J40: =D40/I40 -> 1.0458167 | K40: =(J40/I40) -> 0.52082507 | L40: =IF(OR(Table1[[#This Row],[Actual_Yield (YA)]]="",Table1[[#This Row],[Potential_Yield (YP)]]=""),"",Table1[[#This Row],[Potential_Yield (YP)]]-Table1[[#This Row],[Actual_Yield (YA)]]) -> 11.9
...

Sheet Validation_year_YAChart
B2: Unique_Years | C2: Average_Actual_Yield
B3: {=_xlfn.UNIQUE('Yield_Sensitivity (2)'!C91:C108)} -> 2002 | C3: {=AVERAGE(IF((Table1[Harvest_Year]=Validation_year_YAChart!B3)*(Table1[Climate_Zone]=Zone),Table1[Actual_Yield (YA)]))} -> 2.2
B4: 2003 | C4: {=AVERAGE(IF((Table1[Harvest_Year]=Validation_year_YAChart!B4)*(Table1[Climate_Zone]=Zone),Table1[Actual_Yield (YA)]))} -> 2.1
B5: 2004 | C5: {=AVERAGE(IF((Table1[Harvest_Year]=Validation_year_YAChart!B5)*(Table1[Climate_Zone]=Zone),Table1[Actual_Yield (YA)]))} -> 2.1
B6: 2005 | C6: {=AVERAGE(IF((Table1[Harvest_Year]=Validation_year_YAChart!B6)*(Table1[Climate_Zone]=Zone),Table1[Actual_Yield (YA)]))} -> 2.1
B7: 2006 | C7: {=AVERAGE(IF((Table1[Harvest_Year]=Validation_year_YAChart!B7)*(Table1[Climate_Zone]=Zone),Table1[Actual_Yield (YA)]))} -> 1.9
B8: 2007 | C8: {=AVERAGE(IF((Table1[Harvest_Year]=Validation_year_YAChart!B8)*(Table1[Climate_Zone]=Zone),Table1[Actual_Yield (YA)]))} -> 1.9
B9: 2008 | C9: {=AVERAGE(IF((Table1[Harvest_Year]=Validation_year_YAChart!B9)*(Table1[Climate_Zone]=Zone),Table1[Actual_Yield (YA)]))} -> 1.929
B10: 2009 | C10: {=AVERAGE(IF((Table1[Harvest_Year]=Validation_year_YAChart!B10)*(Table1[Climate_Zone]=Zone),Table1[Actual_Yield (YA)]))} -> 2.355
B11: 2010 | C11: {=AVERAGE(IF((Table1[Harvest_Year]=Validation_year_YAChart!B11)*(Table1[Climate_Zone]=Zone),Table1[Actual_Yield (YA)]))} -> 2.76

Sheet Dashboard
B1: To What Extent are Maize Yield Variation Across Climate Zonen in Nigeria Driven by Climate Stress Versus Management Limitations from Year 2002-2010
G2: Climate Zone
G3: 9701
L6: Havested Year
L7: 2002

Sheet Stress_Index_Conditonal_Formati
A3: Average of Stress_Index | B3: Harvest_Year
A4: Climate_Zone | B4: 2002 | C4: 2003 | D4: 2004 | E4: 2005 | F4: 2006 | G4: 2007 | H4: 2008 | I4: 2009 | J4: 2010 | K4: Grand Total
A5: 9101 | B5: 1.1829653 | C5: 0.97425191 | D5: 0.87173101 | E5: 0.84507042 | F5: 0.8744856 | G5: 0.85186938 | H5: 1.0872042 | I5: 1.0167279 | J5: 0.99236641 | K5: 0.9662969
A6: 9301 | B6: 1.2408872 | C6: 1.0956103 | D6: 0.96631695 | E6: 0.98135427 | F6: 0.93271981 | G6: 0.94792346 | H6: 0.94534963 | I6: 1.2715856 | K6: 1.0477184
A7: 9401 | B7: 1.0146831 | C7: 0.9697108 | D7: 1.0377977 | E7: 1.1003406 | F7: 1.0572953 | G7: 1.0659431 | H7: 1.0510833 | I7: 1.0156356 | J7: 0.97953853 | K7: 1.0324476
A8: 9501 | B8: 1.1488945 | C8: 1.0570511 | D8: 1.0619752 | E8: 0.97999506 | F8: 0.88917467 | G8: 0.84485756 | H8: 0.85231966 | I8: 1.0391946 | J8: 1.2428432 | K8: 1.0129228
A9: 9701 | B9: 1.1671088 | C9: 1.0903427 | D9: 1.0676157 | E9: 1.0458167 | F9: 0.9272816 | G9: 0.90909091 | H9: 0.90520882 | I9: 1.0842541 | J9: 1.2471758 | K9: 1.0493217
A10: 9801 | B10: 1.0143071 | C10: 1.0067292 | D10: 0.94667087 | E10: 0.99190812 | F10: 0.98466003 | G10: 0.97751711 | H10: 1.0090408 | I10: 0.99979715 | J10: 0.99194361 | K10: 0.9913971
A11: 9901 | B11: 0.92411359 | C11: 1.0588061 | D11: 0.99722224 | E11: 1.0454671 | F11: 1.0968979 | G11: 1.0809993 | H11: 0.91716827 | I11: 0.95141394 | J11: 1.0286198 | K11: 1.0111898
A12: 10101 | B12: 1.0084605 | C12: 0.96943567 | D12: 0.94191612 | E12: 0.99793156 | F12: 1.0500626 | G12: 1.0226078 | H12: 1.0148667 | I12: 0.97985184 | J12: 0.9666888 | K12: 0.99464684
A13: 10301 | B13: 1.0508216 | C13: 0.97760398 | D13: 0.91392489 | E13: 0.93603744 | F13: 0.8820935 | G13: 0.83402836 | H13: 0.82124967 | I13: 1.1343695 | J13: 0.99761051 | K13: 0.94974883
A14: 10401 | B14: 1.0357705 | C14: 1.0027384 | D14: 1.0134631 | E14: 1.0524766 | F14: 1.0892189 | G14: 1.0584122 | H14: 0.99439112 | I14: 1.0235006 | J14: 1.0193242 | K14: 1.032144
A15: 10501 | B15: 0.92908021 | C15: 1.0025856 | D15: 1.025475 | E15: 0.9942005 | F15: 1.0179844 | G15: 0.92705255 | H15: 0.97232122 | I15: 0.99250594 | J15: 0.96935585 | K15: 0.98117347
A16: 10901 | B16: 0.85243417 | C16: 0.86190385 | D16: 0.96842921 | E16: 1.0773751 | F16: 1.0897563 | G16: 1.0523151 | H16: 0.94960454 | I16: 0.82751898 | J16: 0.87227414 | K16: 0.95017905
A17: Grand Total | B17: 1.0474605 | C17: 1.0055641 | D17: 0.98437816 | E17: 1.0039978 | F17: 0.99096922 | G17: 0.96438474 | H17: 0.95998399 | I17: 1.0280296 | J17: 1.0279764 | K17: 1.0011678
B19: Stress Index (SI): | C19: Compares Actual Yield to the Expected Yield across each Year; it tells if yield outcome is inflenced by environmental conditions
C20: SI = Actual Yield/Expected Yield
B21: Condition | C21: Interpretation
B22: SI > 1 | C22: Actual Yield > Expected Yield
B23: SI = 1 | C23: Actual Yield = Expected Yield
B24: SI < 1 | C24: Actual Yield < Expected Yield

Sheet SI_Table_Formating
B2: Climate Zones | C2: 2002 | D2: 2003 | E2: 2004 | F2: 2005 | G2: 2006 | H2: 2007 | I2: 2008 | J2: 2009 | K2: 2010 | L2: Total Average SI
B3: 9101 | C3: 1.1829653 | D3: 0.97425191 | E3: 0.87173101 | F3: 0.84507042 | G3: 0.8744856 | H3: 0.85186938 | I3: 1.0872042 | J3: 1.0167279 | K3: 0.99236641 | L3: 0.9662969
B4: 9301 | C4: 1.2408872 | D4: 1.0956103 | E4: 0.96631695 | F4: 0.98135427 | G4: 0.93271981 | H4: 0.94792346 | I4: 0.94534963 | J4: 1.2715856 | L4: 1.0477184 | M4: Conditions | N4: Interpretations
B5: 9401 | C5: 1.0146831 | D5: 0.9697108 | E5: 1.0377977 | F5: 1.1003406 | G5: 1.0572953 | H5: 1.0659431 | I5: 1.0510833 | J5: 1.0156356 | K5: 0.97953853 | L5: 1.0324476 | M5: SI > 1 | N5: Actual Yield > Expected Yield
B6: 9501 | C6: 1.1488945 | D6: 1.0570511 | E6: 1.0619752 | F6: 0.97999506 | G6: 0.88917467 | H6: 0.84485756 | I6: 0.85231966 | J6: 1.0391946 | K6: 1.2428432 | L6: 1.0129228 | M6: SI = 1 | N6: Actual Yield = Expected Yield
B7: 9701 | C7: 1.1671088 | D7: 1.0903427 | E7: 1.0676157 | F7: 1.0458167 | G7: 0.9272816 | H7: 0.90909091 | I7: 0.90520882 | J7: 1.0842541 | K7: 1.2471758 | L7: 1.0493217 | M7: SI < 1 | N7: Actual Yield < Expected Yield
B8: 9801 | C8: 1.0143071 | D8: 1.0067292 | E8: 0.94667087 | F8: 0.99190812 | G8: 0.98466003 | H8: 0.97751711 | I8: 1.0090408 | J8: 0.99979715 | K8: 0.99194361 | L8: 0.9913971
B9: 9901 | C9: 0.92411359 | D9: 1.0588061 | E9: 0.99722224 | F9: 1.0454671 | G9: 1.0968979 | H9: 1.0809993 | I9: 0.91716827 | J9: 0.95141394 | K9: 1.0286198 | L9: 1.0111898
B10: 10101 | C10: 1.0084605 | D10: 0.96943567 | E10: 0.94191612 | F10: 0.99793156 | G10: 1.0500626 | H10: 1.0226078 | I10: 1.0148667 | J10: 0.97985184 | K10: 0.9666888 | L10: 0.99464684
B11: 10301 | C11: 1.0508216 | D11: 0.97760398 | E11: 0.91392489 | F11: 0.93603744 | G11: 0.8820935 | H11: 0.83402836 | I11: 0.82124967 | J11: 1.1343695 | K11: 0.99761051 | L11: 0.94974883
B12: 10401 | C12: 1.0357705 | D12: 1.0027384 | E12: 1.0134631 | F12: 1.0524766 | G12: 1.0892189 | H12: 1.0584122 | I12: 0.99439112 | J12: 1.0235006 | K12: 1.0193242 | L12: 1.032144
B13: 10501 | C13: 0.92908021 | D13: 1.0025856 | E13: 1.025475 | F13: 0.9942005 | G13: 1.0179844 | H13: 0.92705255 | I13: 0.97232122 | J13: 0.99250594 | K13: 0.96935585 | L13: 0.98117347
B14: 10901 | C14: 0.85243417 | D14: 0.86190385 | E14: 0.96842921 | F14: 1.0773751 | G14: 1.0897563 | H14: 1.0523151 | I14: 0.94960454 | J14: 0.82751898 | K14: 0.87227414 | L14: 0.95017905

Sheet Yield_Gap_Chart
B1: Yield Gap Chart
A2: Climate Zone | B2: Yield_Gap | D2: Yield Gap Sorted
A3: {=_xlfn.UNIQUE(Table1[Climate_Zone])} -> 9101 | B3: {=AVERAGE(IF((Table1[Climate_Zone]=Yield_Gap_Chart!A3)*(Table1[Calculated_Yield_Gap]<>""),Table1[Calculated_Yield_Gap]))} -> 9.575 | D3: {=_xlfn._xlws.SORT(A3:B14,2,1)} -> 9101 | E3: 9.575 | G3: =IF(Zone<>D3,E3,NA()) -> 9.575 | H3: =IF(Zone=D3,E3,NA()) -> #N/A
A4: 9301 | B4: {=AVERAGE(IF((Table1[Climate_Zone]=Yield_Gap_Chart!A10)*(Table1[Calculated_Yield_Gap]<>""),Table1[Calculated_Yield_Gap]))} -> 9.8128224 | D4: 9301 | E4: 9.8128224 | G4: =IF(Zone<>D4,E4,NA()) -> 9.8128224 | H4: =IF(Zone=D4,E4,NA()) -> #N/A
A5: 9401 | B5: {=AVERAGE(IF((Table1[Climate_Zone]=Yield_Gap_Chart!A9)*(Table1[Calculated_Yield_Gap]<>""),Table1[Calculated_Yield_Gap]))} -> 11.403398 | D5: 9401 | E5: 11.403398 | G5: =IF(Zone<>D5,E5,NA()) -> 11.403398 | H5: =IF(Zone=D5,E5,NA()) -> #N/A
A6: 9501 | B6: {=AVERAGE(IF((Table1[Climate_Zone]=Yield_Gap_Chart!A5)*(Table1[Calculated_Yield_Gap]<>""),Table1[Calculated_Yield_Gap]))} -> 11.693889 | D6: 9501 | E6: 11.693889 | G6: =IF(Zone<>D6,E6,NA()) -> 11.693889 | H6: =IF(Zone=D6,E6,NA()) -> #N/A
A7: 9701 | B7: {=AVERAGE(IF((Table1[Climate_Zone]=Yield_Gap_Chart!A4)*(Table1[Calculated_Yield_Gap]<>""),Table1[Calculated_Yield_Gap]))} -> 12.535 | D7: 9701 | E7: 12.535 | G7: =IF(Zone<>D7,E7,NA()) -> #N/A | H7: =IF(Zone=D7,E7,NA()) -> 12.535
A8: 9801 | B8: {=AVERAGE(IF((Table1[Climate_Zone]=Yield_Gap_Chart!A8)*(Table1[Calculated_Yield_Gap]<>""),Table1[Calculated_Yield_Gap]))} -> 12.842556 | D8: 9801 | E8: 12.842556 | G8: =IF(Zone<>D8,E8,NA()) -> 12.842556 | H8: =IF(Zone=D8,E8,NA()) -> #N/A
A9: 9901 | B9: {=AVERAGE(IF((Table1[Climate_Zone]=Yield_Gap_Chart!A14)*(Table1[Calculated_Yield_Gap]<>""),Table1[Calculated_Yield_Gap]))} -> 12.970444 | D9: 9901 | E9: 12.970444 | G9: =IF(Zone<>D9,E9,NA()) -> 12.970444 | H9: =IF(Zone=D9,E9,NA()) -> #N/A
A10: 10101 | B10: {=AVERAGE(IF((Table1[Climate_Zone]=Yield_Gap_Chart!A7)*(Table1[Calculated_Yield_Gap]<>""),Table1[Calculated_Yield_Gap]))} -> 13.206222 | D10: 10101 | E10: 13.206222 | G10: =IF(Zone<>D10,E10,NA()) -> 13.206222 | H10: =IF(Zone=D10,E10,NA()) -> #N/A
A11: 10301 | B11: {=AVERAGE(IF((Table1[Climate_Zone]=Yield_Gap_Chart!A13)*(Table1[Calculated_Yield_Gap]<>""),Table1[Calculated_Yield_Gap]))} -> 13.487111 | D11: 10301 | E11: 13.487111 | G11: =IF(Zone<>D11,E11,NA()) -> 13.487111 | H11: =IF(Zone=D11,E11,NA()) -> #N/A
A12: 10401 | B12: {=AVERAGE(IF((Table1[Climate_Zone]=Yield_Gap_Chart!A12)*(Table1[Calculated_Yield_Gap]<>""),Table1[Calculated_Yield_Gap]))} -> 13.561283 | D12: 10401 | E12: 13.561283 | G12: =IF(Zone<>D12,E12,NA()) -> 13.561283 | H12: =IF(Zone=D12,E12,NA()) -> #N/A
A13: 10501 | B13: {=AVERAGE(IF((Table1[Climate_Zone]=Yield_Gap_Chart!A11)*(Table1[Calculated_Yield_Gap]<>""),Table1[Calculated_Yield_Gap]))} -> 13.641556 | D13: 10501 | E13: 13.641556 | G13: =IF(Zone<>D13,E13,NA()) -> 13.641556 | H13: =IF(Zone=D13,E13,NA()) -> #N/A
A14: 10901 | B14: {=AVERAGE(IF((Table1[Climate_Zone]=Yield_Gap_Chart!A6)*(Table1[Calculated_Yield_Gap]<>""),Table1[Calculated_Yield_Gap]))} -> 13.976601 | D14: 10901 | E14: 13.976601 | G14: =IF(Zone<>D14,E14,NA()) -> 13.976601 | H14: =IF(Zone=D14,E14,NA()) -> #N/A

Sheet Dashboard2
P1: Interpretation | Q1: =Interpretation -> Some Climate Stress, Moderate YP | S1: Average Stress index | W1: Unique Label | X1: =Label -> Medium YG + SI < 1
S2: =Avg_SI -> #REF! | U2: Investment Opportunity | V2: =Investment -> Low Opportunity | W2: Average Yield Gap
W3: =Avg_YP -> #REF!
E5: 9701
H30: =Avg_SI -> #REF!

Sheet Dashboard2 (2)
P1: Interpretation | Q1: =Interpretation -> Some Climate Stress, Moderate YP | S1: Average Stress index | W1: Unique Label | X1: =Label -> Medium YG + SI < 1
S2: =Avg_SI -> #REF! | U2: Investment Opportunity | V2: =Investment -> Low Opportunity | W2: Average Yield Gap
W3: =Avg_YP -> #REF!
G6: 9701

Sheet SI_YG_Chart
A1: Climate_Zone | B1: Average of Calculated_Yield_Gap | C1: Average of Stress_Index | E1: Label | F1: Interpretation
A2: 9101 | B2: 9.575 | C2: 0.9662969 | D2: {=_xlfn.IFS(($B2>=$I$5)*($C2<1),"High YG + Climate",($B2>=$I$5)*($C2>1),"High YG + Management",($B2>=$I$5)*($C2=1),"High YG + Normal",($B2<=$I$6)*(C2<1),"Low YG + Climate",(B2<=$I$6)*(C2>1),"Low YG + Management",(B2<=$I$6)*(C2=1),"Low YG + Normal",(B2>$I$6)*(B2<$I$5)*(C2<1),"Medium YG + Climate",(B2>$I$6)*(B2<$I$5)*(C2>1),"Medium YG + Management",(B2>$I$6)*(B2<$I$5)*(C2=1),"Medium YG + Normal")} -> Low YG + Climate | E2: {=_xlfn.IFS(AND($B2>=$I$5,$C2<1),"High YG + Climate",AND($B2>=$I$5,$C2>1),"High YG + Management",AND($B2>=$I$5,$C2=1),"High YG + Normal",AND($B2<=$I$6,$C2<1),"Low YG + Climate",AND($B2<=$I$6,$C2>1),"Low YG + Management",AND($B2<=$I$6,$C2=1),"Low YG + Normal",AND($B2>$I$6,$B2<$I$5,$C2<1),"Medium YG + Climate",AND($B2>$I$6,$B2<$I$5,$C2>1),"Medium YG + Management",AND($B2>$I$6,$B2<$I$5,$C2=1),"Medium YG + Normal")} -> Low YG + Climate | F2: Mainly Climate Constraint
A3: 9301 | B3: 12.535 | C3: 1.0477184 | D3: {=_xlfn.IFS(($B3>=$I$5)*($C3<1),"High YG + Climate",($B3>=$I$5)*($C3>1),"High YG + Management",($B3>=$I$5)*($C3=1),"High YG + Normal",($B3<=$I$6)*(C3<1),"Low YG + Climate",(B3<=$I$6)*(C3>1),"Low YG + Management",(B3<=$I$6)*(C3=1),"Low YG + Normal",(B3>$I$6)*(B3<$I$5)*(C3<1),"Medium YG + Climate",(B3>$I$6)*(B3<$I$5)*(C3>1),"Medium YG + Management",(B3>$I$6)*(B3<$I$5)*(C3=1),"Medium YG + Normal")} -> Medium YG + Management | E3: {=_xlfn.IFS(AND($B3>=$I$5,$C3<1),"High YG + Climate",AND($B3>=$I$5,$C3>1),"High YG + Management",AND($B3>=$I$5,$C3=1),"High YG + Normal",AND($B3<=$I$6,$C3<1),"Low YG + Climate",AND($B3<=$I$6,$C3>1),"Low YG + Management",AND($B3<=$I$6,$C3=1),"Low YG + Normal",AND($B3>$I$6,$B3<$I$5,$C3<1),"Medium YG + Climate",AND($B3>$I$6,$B3<$I$5,$C3>1),"Medium YG + Management",AND($B3>$I$6,$B3<$I$5,$C3=1),"Medium YG + Normal")} -> Medium YG + Management | F3: Management Focus | I3: Defined Threshold for Average Yield Gap
A4: 9401 | B4: 11.693889 | C4: 1.0324476 | D4: {=_xlfn.IFS(($B4>=$I$5)*($C4<1),"High YG + Climate",($B4>=$I$5)*($C4>1),"High YG + Management",($B4>=$I$5)*($C4=1),"High YG + Normal",($B4<=$I$6)*(C4<1),"Low YG + Climate",(B4<=$I$6)*(C4>1),"Low YG + Management",(B4<=$I$6)*(C4=1),"Low YG + Normal",(B4>$I$6)*(B4<$I$5)*(C4<1),"Medium YG + Climate",(B4>$I$6)*(B4<$I$5)*(C4>1),"Medium YG + Management",(B4>$I$6)*(B4<$I$5)*(C4=1),"Medium YG + Normal")} -> Low YG + Management | E4: {=_xlfn.IFS(AND($B4>=$I$5,$C4<1),"High YG + Climate",AND($B4>=$I$5,$C4>1),"High YG + Management",AND($B4>=$I$5,$C4=1),"High YG + Normal",AND($B4<=$I$6,$C4<1),"Low YG + Climate",AND($B4<=$I$6,$C4>1),"Low YG + Management",AND($B4<=$I$6,$C4=1),"Low YG + Normal",AND($B4>$I$6,$B4<$I$5,$C4<1),"Medium YG + Climate",AND($B4>$I$6,$B4<$I$5,$C4>1),"Medium YG + Management",AND($B4>$I$6,$B4<$I$5,$C4=1),"Medium YG + Normal")} -> Low YG + Management | F4: Minor Management Issue | I4: Yield_Gap_Array | J4: Interpretation
A5: 9501 | B5: 13.976601 | C5: 1.0129228 | D5: {=_xlfn.IFS(($B5>=$I$5)*($C5<1),"High YG + Climate",($B5>=$I$5)*($C5>1),"High YG + Management",($B5>=$I$5)*($C5=1),"High YG + Normal",($B5<=$I$6)*(C5<1),"Low YG + Climate",(B5<=$I$6)*(C5>1),"Low YG + Management",(B5<=$I$6)*(C5=1),"Low YG + Normal",(B5>$I$6)*(B5<$I$5)*(C5<1),"Medium YG + Climate",(B5>$I$6)*(B5<$I$5)*(C5>1),"Medium YG + Management",(B5>$I$6)*(B5<$I$5)*(C5=1),"Medium YG + Normal")} -> High YG + Management | E5: {=_xlfn.IFS(AND($B5>=$I$5,$C5<1),"High YG + Climate",AND($B5>=$I$5,$C5>1),"High YG + Management",AND($B5>=$I$5,$C5=1),"High YG + Normal",AND($B5<=$I$6,$C5<1),"Low YG + Climate",AND($B5<=$I$6,$C5>1),"Low YG + Management",AND($B5<=$I$6,$C5=1),"Low YG + Normal",AND($B5>$I$6,$B5<$I$5,$C5<1),"Medium YG + Climate",AND($B5>$I$6,$B5<$I$5,$C5>1),"Medium YG + Management",AND($B5>$I$6,$B5<$I$5,$C5=1),"Medium YG + Normal")} -> High YG + Management | F5: Strong Management Issue | I5: =_xlfn.PERCENTILE.INC('Yield_Sensitivity (2)'!L2:L108,0.75) -> 13.5 | J5: High
A6: 9701 | B6: 13.206222 | C6: 1.0493217 | D6: {=_xlfn.IFS(($B6>=$I$5)*($C6<1),"High YG + Climate",($B6>=$I$5)*($C6>1),"High YG + Management",($B6>=$I$5)*($C6=1),"High YG + Normal",($B6<=$I$6)*(C6<1),"Low YG + Climate",(B6<=$I$6)*(C6>1),"Low YG + Management",(B6<=$I$6)*(C6=1),"Low YG + Normal",(B6>$I$6)*(B6<$I$5)*(C6<1),"Medium YG + Climate",(B6>$I$6)*(B6<$I$5)*(C6>1),"Medium YG + Management",(B6>$I$6)*(B6<$I$5)*(C6=1),"Medium YG + Normal")} -> Medium YG + Management | E6: {=_xlfn.IFS(AND($B6>=$I$5,$C6<1),"High YG + Climate",AND($B6>=$I$5,$C6>1),"High YG + Management",AND($B6>=$I$5,$C6=1),"High YG + Normal",AND($B6<=$I$6,$C6<1),"Low YG + Climate",AND($B6<=$I$6,$C6>1),"Low YG + Management",AND($B6<=$I$6,$C6=1),"Low YG + Normal",AND($B6>$I$6,$B6<$I$5,$C6<1),"Medium YG + Climate",AND($B6>$I$6,$B6<$I$5,$C6>1),"Medium YG + Management",AND($B6>$I$6,$B6<$I$5,$C6=1),"Medium YG + Normal")} -> Medium YG + Management | F6: Management Focus | I6: =_xlfn.PERCENTILE.INC('Yield_Sensitivity (2)'!L2:L108,0.25) -> 11.9225 | J6: Low
A7: 9801 | B7: 12.842556 | C7: 0.9913971 | D7: {=_xlfn.IFS(($B7>=$I$5)*($C7<1),"High YG + Climate",($B7>=$I$5)*($C7>1),"High YG + Management",($B7>=$I$5)*($C7=1),"High YG + Normal",($B7<=$I$6)*(C7<1),"Low YG + Climate",(B7<=$I$6)*(C7>1),"Low YG + Management",(B7<=$I$6)*(C7=1),"Low YG + Normal",(B7>$I$6)*(B7<$I$5)*(C7<1),"Medium YG + Climate",(B7>$I$6)*(B7<$I$5)*(C7>1),"Medium YG + Management",(B7>$I$6)*(B7<$I$5)*(C7=1),"Medium YG + Normal")} -> Medium YG + Climate | E7: {=_xlfn.IFS(AND($B7>=$I$5,$C7<1),"High YG + Climate",AND($B7>=$I$5,$C7>1),"High YG + Management",AND($B7>=$I$5,$C7=1),"High YG + Normal",AND($B7<=$I$6,$C7<1),"Low YG + Climate",AND($B7<=$I$6,$C7>1),"Low YG + Management",AND($B7<=$I$6,$C7=1),"Low YG + Normal",AND($B7>$I$6,$B7<$I$5,$C7<1),"Medium YG + Climate",AND($B7>$I$6,$B7<$I$5,$C7>1),"Medium YG + Management",AND($B7>$I$6,$B7<$I$5,$C7=1),"Medium YG + Normal")} -> Medium YG + Climate | F7: Some Climate Stress, Moderate YP | I7: =_xlfn.PERCENTILE.INC('Yield_Sensitivity (2)'!L3:L109,0.5) -> 12.7 | J7: Medium
A8: 9901 | B8: 11.403398 | C8: 1.0111898 | D8: {=_xlfn.IFS(($B8>=$I$5)*($C8<1),"High YG + Climate",($B8>=$I$5)*($C8>1),"High YG + Management",($B8>=$I$5)*($C8=1),"High YG + Normal",($B8<=$I$6)*(C8<1),"Low YG + Climate",(B8<=$I$6)*(C8>1),"Low YG + Management",(B8<=$I$6)*(C8=1),"Low YG + Normal",(B8>$I$6)*(B8<$I$5)*(C8<1),"Medium YG + Climate",(B8>$I$6)*(B8<$I$5)*(C8>1),"Medium YG + Management",(B8>$I$6)*(B8<$I$5)*(C8=1),"Medium YG + Normal")} -> Low YG + Management | E8: {=_xlfn.IFS(AND($B8>=$I$5,$C8<1),"High YG + Climate",AND($B8>=$I$5,$C8>1),"High YG + Management",AND($B8>=$I$5,$C8=1),"High YG + Normal",AND($B8<=$I$6,$C8<1),"Low YG + Climate",AND($B8<=$I$6,$C8>1),"Low YG + Management",AND($B8<=$I$6,$C8=1),"Low YG + Normal",AND($B8>$I$6,$B8<$I$5,$C8<1),"Medium YG + Climate",AND($B8>$I$6,$B8<$I$5,$C8>1),"Medium YG + Management",AND($B8>$I$6,$B8<$I$5,$C8=1),"Medium YG + Normal")} -> Low YG + Management | F8: Minor Management Issue | I8: Defined Threshold for Average Stress Index
A9: 10101 | B9: 9.8128224 | C9: 0.99464684 | D9: {=_xlfn.IFS(($B9>=$I$5)*($C9<1),"High YG + Climate",($B9>=$I$5)*($C9>1),"High YG + Management",($B9>=$I$5)*($C9=1),"High YG + Normal",($B9<=$I$6)*(C9<1),"Low YG + Climate",(B9<=$I$6)*(C9>1),"Low YG + Management",(B9<=$I$6)*(C9=1),"Low YG + Normal",(B9>$I$6)*(B9<$I$5)*(C9<1),"Medium YG + Climate",(B9>$I$6)*(B9<$I$5)*(C9>1),"Medium YG + Management",(B9>$I$6)*(B9<$I$5)*(C9=1),"Medium YG + Normal")} -> Low YG + Climate | E9: {=_xlfn.IFS(AND($B9>=$I$5,$C9<1),"High YG + Climate",AND($B9>=$I$5,$C9>1),"High YG + Management",AND($B9>=$I$5,$C9=1),"High YG + Normal",AND($B9<=$I$6,$C9<1),"Low YG + Climate",AND($B9<=$I$6,$C9>1),"Low YG + Management",AND($B9<=$I$6,$C9=1),"Low YG + Normal",AND($B9>$I$6,$B9<$I$5,$C9<1),"Medium YG + Climate",AND($B9>$I$6,$B9<$I$5,$C9>1),"Medium YG + Management",AND($B9>$I$6,$B9<$I$5,$C9=1),"Medium YG + Normal")} -> Low YG + Climate | F9: Mainly Climate Constraint | I9: Conditions | J9: Interpretation
A10: 10301 | B10: 13.641556 | C10: 0.94974883 | D10: {=_xlfn.IFS(($B10>=$I$5)*($C10<1),"High YG + Climate",($B10>=$I$5)*($C10>1),"High YG + Management",($B10>=$I$5)*($C10=1),"High YG + Normal",($B10<=$I$6)*(C10<1),"Low YG + Climate",(B10<=$I$6)*(C10>1),"Low YG + Management",(B10<=$I$6)*(C10=1),"Low YG + Normal",(B10>$I$6)*(B10<$I$5)*(C10<1),"Medium YG + Climate",(B10>$I$6)*(B10<$I$5)*(C10>1),"Medium YG + Management",(B10>$I$6)*(B10<$I$5)*(C10=1),"Medium YG + Normal")} -> High YG + Climate | E10: {=_xlfn.IFS(AND($B10>=$I$5,$C10<1),"High YG + Climate",AND($B10>=$I$5,$C10>1),"High YG + Management",AND($B10>=$I$5,$C10=1),"High YG + Normal",AND($B10<=$I$6,$C10<1),"Low YG + Climate",AND($B10<=$I$6,$C10>1),"Low YG + Management",AND($B10<=$I$6,$C10=1),"Low YG + Normal",AND($B10>$I$6,$B10<$I$5,$C10<1),"Medium YG + Climate",AND($B10>$I$6,$B10<$I$5,$C10>1),"Medium YG + Management",AND($B10>$I$6,$B10<$I$5,$C10=1),"Medium YG + Normal")} -> High YG + Climate | F10: Both Poor Management and Climate Stress | I10: SI > 1 | J10: Unstressed condition
